2021-06-28 14:05:49,509 - E:\GitHub repository\Audit\logis_fir\tools.py[line:37] - ERROR: 错误:Traceback (most recent call last):
  File "E:\GitHub repository\Audit\logis_fir\tools.py", line 29, in executeSql
    cur.execute(sql)
sqlite3.OperationalError: no such column: 委办主任签批意见

2021-06-28 14:12:27,377 - E:\GitHub repository\Audit\logis_fir\tools.py[line:37] - ERROR: 错误:Traceback (most recent call last):
  File "E:\GitHub repository\Audit\logis_fir\tools.py", line 29, in executeSql
    cur.execute(sql)
sqlite3.OperationalError: no such column: corfile.起草处室

2021-06-28 15:01:57,914 - E:\GitHub repository\Audit\logis_fir\tools.py[line:37] - ERROR: 错误:Traceback (most recent call last):
  File "E:\GitHub repository\Audit\logis_fir\tools.py", line 29, in executeSql
    cur.execute(sql)
sqlite3.OperationalError: DISTINCT aggregates must have exactly one argument

2021-06-28 15:02:51,848 - E:\GitHub repository\Audit\logis_fir\tools.py[line:37] - ERROR: 错误:Traceback (most recent call last):
  File "E:\GitHub repository\Audit\logis_fir\tools.py", line 29, in executeSql
    cur.execute(sql)
sqlite3.OperationalError: near ",": syntax error

2021-06-28 15:12:42,061 - E:\GitHub repository\Audit\logis_fir\tools.py[line:37] - ERROR: 错误:Traceback (most recent call last):
  File "E:\GitHub repository\Audit\logis_fir\tools.py", line 29, in executeSql
    cur.execute(sql)
sqlite3.OperationalError: DISTINCT aggregates must have exactly one argument

2021-06-28 15:17:03,140 - E:\GitHub repository\Audit\logis_fir\tools.py[line:37] - ERROR: 错误:Traceback (most recent call last):
  File "E:\GitHub repository\Audit\logis_fir\tools.py", line 29, in executeSql
    cur.execute(sql)
sqlite3.OperationalError: DISTINCT aggregates must have exactly one argument

2021-06-28 15:17:15,685 - E:\GitHub repository\Audit\logis_fir\tools.py[line:37] - ERROR: 错误:Traceback (most recent call last):
  File "E:\GitHub repository\Audit\logis_fir\tools.py", line 29, in executeSql
    cur.execute(sql)
sqlite3.OperationalError: near "'
'": syntax error

2021-06-28 15:18:24,601 - E:\GitHub repository\Audit\logis_fir\tools.py[line:37] - ERROR: 错误:Traceback (most recent call last):
  File "E:\GitHub repository\Audit\logis_fir\tools.py", line 29, in executeSql
    cur.execute(sql)
sqlite3.OperationalError: DISTINCT aggregates must have exactly one argument

2021-06-28 15:20:34,368 - E:\GitHub repository\Audit\logis_fir\tools.py[line:37] - ERROR: 错误:Traceback (most recent call last):
  File "E:\GitHub repository\Audit\logis_fir\tools.py", line 29, in executeSql
    cur.execute(sql)
sqlite3.OperationalError: near "[,'
']": syntax error

2021-06-28 15:22:19,228 - E:\GitHub repository\Audit\logis_fir\tools.py[line:37] - ERROR: 错误:Traceback (most recent call last):
  File "E:\GitHub repository\Audit\logis_fir\tools.py", line 29, in executeSql
    cur.execute(sql)
sqlite3.OperationalError: no such column: 
'

2021-06-28 15:34:39,872 - E:\GitHub repository\Audit\logis_fir\tools.py[line:37] - ERROR: 错误:Traceback (most recent call last):
  File "E:\GitHub repository\Audit\logis_fir\tools.py", line 29, in executeSql
    cur.execute(sql)
sqlite3.OperationalError: near ")": syntax error

2021-06-28 15:34:58,201 - E:\GitHub repository\Audit\logis_fir\tools.py[line:37] - ERROR: 错误:Traceback (most recent call last):
  File "E:\GitHub repository\Audit\logis_fir\tools.py", line 29, in executeSql
    cur.execute(sql)
sqlite3.OperationalError: near ")": syntax error

2021-06-28 15:35:16,113 - E:\GitHub repository\Audit\logis_fir\tools.py[line:37] - ERROR: 错误:Traceback (most recent call last):
  File "E:\GitHub repository\Audit\logis_fir\tools.py", line 29, in executeSql
    cur.execute(sql)
sqlite3.OperationalError: wrong number of arguments to function replace()

2021-06-28 15:35:37,629 - E:\GitHub repository\Audit\logis_fir\tools.py[line:37] - ERROR: 错误:Traceback (most recent call last):
  File "E:\GitHub repository\Audit\logis_fir\tools.py", line 29, in executeSql
    cur.execute(sql)
sqlite3.OperationalError: wrong number of arguments to function replace()

2021-06-28 15:37:27,609 - E:\GitHub repository\Audit\logis_fir\tools.py[line:37] - ERROR: 错误:Traceback (most recent call last):
  File "E:\GitHub repository\Audit\logis_fir\tools.py", line 29, in executeSql
    cur.execute(sql)
sqlite3.OperationalError: wrong number of arguments to function replace()

2021-06-28 15:40:16,261 - E:\GitHub repository\Audit\logis_fir\tools.py[line:37] - ERROR: 错误:Traceback (most recent call last):
  File "E:\GitHub repository\Audit\logis_fir\tools.py", line 29, in executeSql
    cur.execute(sql)
sqlite3.OperationalError: near "FROM": syntax error

2021-06-28 15:42:01,779 - E:\GitHub repository\Audit\logis_fir\tools.py[line:46] - ERROR: 错误:Traceback (most recent call last):
  File "E:\GitHub repository\Audit\logis_fir\tools.py", line 43, in copyFile
    shutil.copy(source, target)
  File "E:\Anaconda\envs\Audit problem rectification\lib\shutil.py", line 415, in copy
    copyfile(src, dst, follow_symlinks=follow_symlinks)
  File "E:\Anaconda\envs\Audit problem rectification\lib\shutil.py", line 261, in copyfile
    with open(src, 'rb') as fsrc, open(dst, 'wb') as fdst:
FileNotFoundError: [Errno 2] No such file or directory: ''

2021-06-28 17:09:13,000 - E:\GitHub repository\Audit\logis_fir\tools.py[line:46] - ERROR: 错误:Traceback (most recent call last):
  File "E:\GitHub repository\Audit\logis_fir\tools.py", line 43, in copyFile
    shutil.copy(source, target)
  File "E:\Anaconda\envs\Audit problem rectification\lib\shutil.py", line 415, in copy
    copyfile(src, dst, follow_symlinks=follow_symlinks)
  File "E:\Anaconda\envs\Audit problem rectification\lib\shutil.py", line 261, in copyfile
    with open(src, 'rb') as fsrc, open(dst, 'wb') as fdst:
FileNotFoundError: [Errno 2] No such file or directory: ''

2021-06-28 17:30:46,432 - E:\GitHub repository\Audit\logis_fir\tools.py[line:46] - ERROR: 错误:Traceback (most recent call last):
  File "E:\GitHub repository\Audit\logis_fir\tools.py", line 43, in copyFile
    shutil.copy(source, target)
  File "E:\Anaconda\envs\Audit problem rectification\lib\shutil.py", line 415, in copy
    copyfile(src, dst, follow_symlinks=follow_symlinks)
  File "E:\Anaconda\envs\Audit problem rectification\lib\shutil.py", line 261, in copyfile
    with open(src, 'rb') as fsrc, open(dst, 'wb') as fdst:
FileNotFoundError: [Errno 2] No such file or directory: ''

2021-06-28 18:29:05,419 - E:\GitHub repository\Audit\logis_fir\tools.py[line:46] - ERROR: 错误:Traceback (most recent call last):
  File "E:\GitHub repository\Audit\logis_fir\tools.py", line 43, in copyFile
    shutil.copy(source, target)
  File "E:\Anaconda\envs\Audit problem rectification\lib\shutil.py", line 415, in copy
    copyfile(src, dst, follow_symlinks=follow_symlinks)
  File "E:\Anaconda\envs\Audit problem rectification\lib\shutil.py", line 261, in copyfile
    with open(src, 'rb') as fsrc, open(dst, 'wb') as fdst:
FileNotFoundError: [Errno 2] No such file or directory: ''

2021-06-28 20:05:22,252 - E:\GitHub repository\Audit\logis_fir\tools.py[line:46] - ERROR: 错误:Traceback (most recent call last):
  File "E:\GitHub repository\Audit\logis_fir\tools.py", line 43, in copyFile
    shutil.copy(source, target)
  File "E:\Anaconda\envs\Audit problem rectification\lib\shutil.py", line 415, in copy
    copyfile(src, dst, follow_symlinks=follow_symlinks)
  File "E:\Anaconda\envs\Audit problem rectification\lib\shutil.py", line 261, in copyfile
    with open(src, 'rb') as fsrc, open(dst, 'wb') as fdst:
FileNotFoundError: [Errno 2] No such file or directory: ''

