2021-06-30 22:05:35,692 - E:\GitHub repository\Audit\logis_fir\tools.py[line:37] - ERROR: 错误:Traceback (most recent call last):
  File "E:\GitHub repository\Audit\logis_fir\tools.py", line 29, in executeSql
    cur.execute(sql)
sqlite3.OperationalError: near "/": syntax error

2021-07-01 00:18:16,386 - E:\GitHub repository\Audit\logis_fir\tools.py[line:37] - ERROR: 错误:Traceback (most recent call last):
  File "E:\GitHub repository\Audit\logis_fir\tools.py", line 29, in executeSql
    cur.execute(sql)
sqlite3.OperationalError: no such column: 审计报告文号

2021-07-01 00:18:23,413 - E:\GitHub repository\Audit\logis_fir\tools.py[line:37] - ERROR: 错误:Traceback (most recent call last):
  File "E:\GitHub repository\Audit\logis_fir\tools.py", line 29, in executeSql
    cur.execute(sql)
sqlite3.OperationalError: no such column: 审计报告文号

2021-07-01 01:29:37,435 - E:\GitHub repository\Audit\logis_fir\tools.py[line:37] - ERROR: 错误:Traceback (most recent call last):
  File "E:\GitHub repository\Audit\logis_fir\tools.py", line 29, in executeSql
    cur.execute(sql)
sqlite3.OperationalError: near "set": syntax error

2021-07-01 01:29:46,727 - E:\GitHub repository\Audit\logis_fir\tools.py[line:37] - ERROR: 错误:Traceback (most recent call last):
  File "E:\GitHub repository\Audit\logis_fir\tools.py", line 29, in executeSql
    cur.execute(sql)
sqlite3.OperationalError: near "set": syntax error

2021-07-01 01:29:46,727 - E:\GitHub repository\Audit\logis_fir\tools.py[line:37] - ERROR: 错误:Traceback (most recent call last):
  File "E:\GitHub repository\Audit\logis_fir\tools.py", line 29, in executeSql
    cur.execute(sql)
sqlite3.OperationalError: near "set": syntax error

2021-07-01 01:30:27,940 - E:\GitHub repository\Audit\logis_fir\tools.py[line:37] - ERROR: 错误:Traceback (most recent call last):
  File "E:\GitHub repository\Audit\logis_fir\tools.py", line 29, in executeSql
    cur.execute(sql)
sqlite3.OperationalError: near "set": syntax error

2021-07-01 01:30:27,940 - E:\GitHub repository\Audit\logis_fir\tools.py[line:37] - ERROR: 错误:Traceback (most recent call last):
  File "E:\GitHub repository\Audit\logis_fir\tools.py", line 29, in executeSql
    cur.execute(sql)
sqlite3.OperationalError: near "set": syntax error

2021-07-01 01:30:27,940 - E:\GitHub repository\Audit\logis_fir\tools.py[line:37] - ERROR: 错误:Traceback (most recent call last):
  File "E:\GitHub repository\Audit\logis_fir\tools.py", line 29, in executeSql
    cur.execute(sql)
sqlite3.OperationalError: near "set": syntax error

2021-08-31 18:53:10,489 - E:\GitHub repository\Audit\logis_fir\tools.py[line:37] - ERROR: 错误:Traceback (most recent call last):
  File "E:\GitHub repository\Audit\logis_fir\tools.py", line 29, in executeSql
    cur.execute(sql)
sqlite3.OperationalError: no such table: bw_cast_cor

2021-08-31 18:53:22,753 - E:\GitHub repository\Audit\logis_fir\tools.py[line:37] - ERROR: 错误:Traceback (most recent call last):
  File "E:\GitHub repository\Audit\logis_fir\tools.py", line 29, in executeSql
    cur.execute(sql)
sqlite3.OperationalError: no such table: bw_cast_cor

2021-08-31 19:52:34,296 - E:\GitHub repository\Audit\logis_fir\tools.py[line:37] - ERROR: 错误:Traceback (most recent call last):
  File "E:\GitHub repository\Audit\logis_fir\tools.py", line 29, in executeSql
    cur.execute(sql)
sqlite3.OperationalError: no such table: bw_cast_cor

2021-08-31 20:21:19,936 - E:\GitHub repository\Audit\logis_fir\tools.py[line:37] - ERROR: 错误:Traceback (most recent call last):
  File "E:\GitHub repository\Audit\logis_fir\tools.py", line 29, in executeSql
    cur.execute(sql)
sqlite3.OperationalError: no such table: bw_cast_cor

2021-08-31 20:21:24,578 - E:\GitHub repository\Audit\logis_fir\tools.py[line:37] - ERROR: 错误:Traceback (most recent call last):
  File "E:\GitHub repository\Audit\logis_fir\tools.py", line 29, in executeSql
    cur.execute(sql)
sqlite3.OperationalError: no such table: bw_cast_cor

2021-08-31 21:33:49,995 - E:\GitHub repository\Audit\logis_fir\tools.py[line:37] - ERROR: 错误:Traceback (most recent call last):
  File "E:\GitHub repository\Audit\logis_fir\tools.py", line 29, in executeSql
    cur.execute(sql)
sqlite3.OperationalError: no such table: bw_cast_cor

2021-08-31 21:44:46,045 - E:\GitHub repository\Audit\logis_fir\call_index.py[line:1356] - ERROR: 错误:Traceback (most recent call last):
  File "E:\GitHub repository\Audit\logis_fir\call_index.py", line 1342, in importExcelProblemJz
    self.displayProblemJzPage()
  File "E:\GitHub repository\Audit\logis_fir\call_index.py", line 666, in displayProblemJzPage
    data = tools.sortByKey(data, 5, 2)
  File "E:\GitHub repository\Audit\logis_fir\tools.py", line 117, in sortByKey
    data.sort(key=lambda x: (-int(cls.getIntegerFromString(x[index])[0]),
  File "E:\GitHub repository\Audit\logis_fir\tools.py", line 118, in <lambda>
    int(cls.getIntegerFromString(x[index])[1])))
IndexError: list index out of range

2021-08-31 21:48:00,358 - E:\GitHub repository\Audit\logis_fir\call_index.py[line:1358] - ERROR: 错误:Traceback (most recent call last):
  File "E:\GitHub repository\Audit\logis_fir\call_index.py", line 1344, in importExcelProblemJz
    QtWidgets.QMessageBox.critical(self, "错误", "问题表导入失败！")
  File "E:\GitHub repository\Audit\logis_fir\call_index.py", line 668, in displayProblemJzPage
    # 已经完成录入
  File "E:\GitHub repository\Audit\logis_fir\tools.py", line 117, in sortByKey
    data.sort(key=lambda x: (-int(cls.getIntegerFromString(x[index])[0]),
  File "E:\GitHub repository\Audit\logis_fir\tools.py", line 118, in <lambda>
    int(cls.getIntegerFromString(x[index])[1])))
IndexError: list index out of range

